Workbook

Sheet Как пользоваться
A1: Карта связей прототипа — фаза 0
A3: Эталонная карта переходов: как экраны должны быть связаны. Состав экранов приведён к прототипу и паспорту сервиса: клиентская часть (лендинг, запись в четыре шага без предоплаты, кабинет) и раздел администратора. Кабинета мастера, оплат, листа ожидания, сообщений, отзывов и аналитики в продукте нет.
A4: Эталонная карта переходов: как экраны должны быть связаны. Кабинеты мастера и администратора собраны по спроектированным экранам, клиентская часть — по результатам сверки с проектом (лендинг с якорным меню, четыре шага записи без предоплаты, кабинет из пяти пунктов).
A6: Листы
A7: Реестр — все страницы, модалки, шторки и состояния с ID. Колонки «Исходящих», «Входящих» и «Проверка» считаются автоматически.
A8: Навигация — повторяющиеся элементы: шапки, подвал, меню, таб-бар, переключатель ролей.
A9: Связи — переходы внутри содержимого страниц, по блокам.
A10: Сценарии — сквозные пути для финальной проверки.
A11: Вопросы — что нужно решить до связывания.
A12: Сводка — счётчики по блокам: сироты, тупики, прогресс.
A14: Цвета
A15: Жёлтые ячейки заполняете вы: название в проекте, статус сверки, статус применения.
... A32: 25.09.2026 реестр, навигация, связи, сценарии и вопросы сверены с Prototype/Прототип - Ноготочки.dc.html и Лендинг - Ноготочки.dc.html. Экраны, которых нет в прототипе и которые исключает паспорт, удалены вместе со своими связями. Факт по каждому пункту — в колонках «Комментарий сверки» и «Факт в прототипе». Строки с примечанием «Добавлено при сверке» — экраны и переходы, которых раньше не было в карте.

Sheet Сводка
A1: Блок | B1: Страниц | C1: Связей из блока | D1: Связано | E1: Нет элемента | F1: Требует решения | G1: Сирот | H1: Тупиков | I1: Не сверено
A2: PUB | B2: =COUNTIF(Реестр!$B:$B,A2) | C2: =COUNTIF(Связи!$B:$B,A2) | D2: =COUNTIFS(Связи!$B:$B,A2,Связи!$J:$J,"Связано") | E2: =COUNTIFS(Связи!$B:$B,A2,Связи!$J:$J,"Нет элемента") | F2: =COUNTIFS(Связи!$B:$B,A2,Связи!$J:$J,"Требует решения") | G2: =COUNTIFS(Реестр!$B:$B,A2,Реестр!$L:$L,"⚠ сирота") | H2: =COUNTIFS(Реестр!$B:$B,A2,Реестр!$L:$L,"⚠ тупик") | I2: =COUNTIFS(Реестр!$B:$B,A2,Реестр!$I:$I,"Не сверено")
A3: AUTH | B3: =COUNTIF(Реестр!$B:$B,A3) | C3: =COUNTIF(Связи!$B:$B,A3) | D3: =COUNTIFS(Связи!$B:$B,A3,Связи!$J:$J,"Связано") | E3: =COUNTIFS(Связи!$B:$B,A3,Связи!$J:$J,"Нет элемента") | F3: =COUNTIFS(Связи!$B:$B,A3,Связи!$J:$J,"Требует решения") | G3: =COUNTIFS(Реестр!$B:$B,A3,Реестр!$L:$L,"⚠ сирота") | H3: =COUNTIFS(Реестр!$B:$B,A3,Реестр!$L:$L,"⚠ тупик") | I3: =COUNTIFS(Реестр!$B:$B,A3,Реестр!$I:$I,"Не сверено")
A4: BOOK | B4: =COUNTIF(Реестр!$B:$B,A4) | C4: =COUNTIF(Связи!$B:$B,A4) | D4: =COUNTIFS(Связи!$B:$B,A4,Связи!$J:$J,"Связано") | E4: =COUNTIFS(Связи!$B:$B,A4,Связи!$J:$J,"Нет элемента") | F4: =COUNTIFS(Связи!$B:$B,A4,Связи!$J:$J,"Требует решения") | G4: =COUNTIFS(Реестр!$B:$B,A4,Реестр!$L:$L,"⚠ сирота") | H4: =COUNTIFS(Реестр!$B:$B,A4,Реестр!$L:$L,"⚠ тупик") | I4: =COUNTIFS(Реестр!$B:$B,A4,Реестр!$I:$I,"Не сверено")
A5: CAB | B5: =COUNTIF(Реестр!$B:$B,A5) | C5: =COUNTIF(Связи!$B:$B,A5) | D5: =COUNTIFS(Связи!$B:$B,A5,Связи!$J:$J,"Связано") | E5: =COUNTIFS(Связи!$B:$B,A5,Связи!$J:$J,"Нет элемента") | F5: =COUNTIFS(Связи!$B:$B,A5,Связи!$J:$J,"Требует решения") | G5: =COUNTIFS(Реестр!$B:$B,A5,Реестр!$L:$L,"⚠ сирота") | H5: =COUNTIFS(Реестр!$B:$B,A5,Реестр!$L:$L,"⚠ тупик") | I5: =COUNTIFS(Реестр!$B:$B,A5,Реестр!$I:$I,"Не сверено")
A6: A | B6: =COUNTIF(Реестр!$B:$B,A6) | C6: =COUNTIF(Связи!$B:$B,A6) | D6: =COUNTIFS(Связи!$B:$B,A6,Связи!$J:$J,"Связано") | E6: =COUNTIFS(Связи!$B:$B,A6,Связи!$J:$J,"Нет элемента") | F6: =COUNTIFS(Связи!$B:$B,A6,Связи!$J:$J,"Требует решения") | G6: =COUNTIFS(Реестр!$B:$B,A6,Реестр!$L:$L,"⚠ сирота") | H6: =COUNTIFS(Реестр!$B:$B,A6,Реестр!$L:$L,"⚠ тупик") | I6: =COUNTIFS(Реестр!$B:$B,A6,Реестр!$I:$I,"Не сверено")
A7: SYS | B7: =COUNTIF(Реестр!$B:$B,A7) | C7: =COUNTIF(Связи!$B:$B,A7) | D7: =COUNTIFS(Связи!$B:$B,A7,Связи!$J:$J,"Связано") | E7: =COUNTIFS(Связи!$B:$B,A7,Связи!$J:$J,"Нет элемента") | F7: =COUNTIFS(Связи!$B:$B,A7,Связи!$J:$J,"Требует решения") | G7: =COUNTIFS(Реестр!$B:$B,A7,Реестр!$L:$L,"⚠ сирота") | H7: =COUNTIFS(Реестр!$B:$B,A7,Реестр!$L:$L,"⚠ тупик") | I7: =COUNTIFS(Реестр!$B:$B,A7,Реестр!$I:$I,"Не сверено")
A8: DS | B8: =COUNTIF(Реестр!$B:$B,A8) | C8: =COUNTIF(Связи!$B:$B,A8) | D8: =COUNTIFS(Связи!$B:$B,A8,Связи!$J:$J,"Связано") | E8: =COUNTIFS(Связи!$B:$B,A8,Связи!$J:$J,"Нет элемента") | F8: =COUNTIFS(Связи!$B:$B,A8,Связи!$J:$J,"Требует решения") | G8: =COUNTIFS(Реестр!$B:$B,A8,Реестр!$L:$L,"⚠ сирота") | H8: =COUNTIFS(Реестр!$B:$B,A8,Реестр!$L:$L,"⚠ тупик") | I8: =COUNTIFS(Реестр!$B:$B,A8,Реестр!$I:$I,"Не сверено")
A9: Итого | B9: =SUM(B2:B8) | C9: =SUM(C2:C8) | D9: =SUM(D2:D8) | E9: =SUM(E2:E8) | F9: =SUM(F2:F8) | G9: =SUM(G2:G8) | H9: =SUM(H2:H8) | I9: =SUM(I2:I8)
A10: Навигация: пунктов всего | C10: =COUNTA(Навигация!$A:$A)-1
A11: Навигация: связано | C11: =COUNTIF(Навигация!$J:$J,"Связано")

Sheet Реестр
A1: ID | B1: Блок | C1: Название (ожидаемое) | D1: Тип | E1: Роль | F1: Родитель | G1: Навигация | H1: Название в проекте | I1: Сверка | J1: Исходящих | K1: Входящих | L1: Проверка | M1: Примечание | N1: Комментарий сверки
A2: PUB-01 | B2: PUB | C2: Лендинг (секции: Услуги, Как это работает, Мастера, Работы, Контакты, Отзывы, Призыв записаться) | D2: Страница | E2: Клиент | G2: NAV-LAND | H2: Лендинг - Ноготочки.dc.html | I2: Совпадает | J2: =COUNTIF(Связи!$C:$C,A2)+IF(G2="",0,COUNTIF(Навигация!$B:$B,G2)) | K2: =COUNTIF(Связи!$G:$G,A2)+COUNTIF(Навигация!$F:$F,A2) | L2: =IF(D2="Дизайн-система","вне графа",IF(AND(K2=0,OR(D2="Состояние",D2="Служебная")),"демо / вход по событию",IF(K2=0,"⚠ сирота",IF(J2=0,"⚠ тупик","ок")))) | M2: Точка входа клиента. Якорное меню, отдельных страниц секций нет | N2: Отдельный файл. Секции: первый экран, полоса доверия, как это работает, услуги, мастера, галерея работ, отзывы (только отзывы-цитаты, без формы), контакты, финальный призыв, подвал
A3: PUB-05 | B3: PUB | C3: Профиль мастера (публичный) | D3: Страница | E3: Клиент | G3: NAV-LAND | H3: #/masters/:id · «Профиль мастера» | I3: Совпадает | J3: =COUNTIF(Связи!$C:$C,A3)+IF(G3="",0,COUNTIF(Навигация!$B:$B,G3)) | K3: =COUNTIF(Связи!$G:$G,A3)+COUNTIF(Навигация!$F:$F,A3) | L3: =IF(D3="Дизайн-система","вне графа",IF(AND(K3=0,OR(D3="Состояние",D3="Служебная")),"демо / вход по событию",IF(K3=0,"⚠ сирота",IF(J3=0,"⚠ тупик","ок")))) | M3: Единственная внутренняя страница публичной части | N3: Своя простая шапка: «← Назад» и логотип. Шапки лендинга с якорями нет · 25.09.2026: блок «Работы мастера» — опубликованные фото из A-12; цены по уровню мастера
A4: AUTH-01 | B4: AUTH | C4: Вход клиента (телефон или e-mail и пароль; вход по коду из SMS) | D4: Страница | E4: Клиент | H4: #/login · «Вход» | I4: Совпадает | J4: =COUNTIF(Связи!$C:$C,A4)+IF(G4="",0,COUNTIF(Навигация!$B:$B,G4)) | K4: =COUNTIF(Связи!$G:$G,A4)+COUNTIF(Навигация!$F:$F,A4) | L4: =IF(D4="Дизайн-система","вне графа",IF(AND(K4=0,OR(D4="Состояние",D4="Служебная")),"демо / вход по событию",IF(K4=0,"⚠ сирота",IF(J4=0,"⚠ тупик","ок")))) | M4: Сверить | N4: Вход по телефону или e-mail и паролю (как в паспорте), а не по коду. Код из SMS — ссылкой «Войти по коду из SMS» · 25.09.2026: ожидаемое название приведено к схеме БД — вход по телефону или e-mail и паролю (users.phone, users.email, users.password_hash)
A5: AUTH-02 | B5: AUTH | C5: Подтверждение кодом (телефон, e-mail, вход по коду, сброс пароля) | D5: Страница | E5: Клиент | H5: #/verify · «Подтверждение телефона» | I5: Совпадает | J5: =COUNTIF(Связи!$C:$C,A5)+IF(G5="",0,COUNTIF(Навигация!$B:$B,G5)) | K5: =COUNTIF(Связи!$G:$G,A5)+COUNTIF(Навигация!$F:$F,A5) | L5: =IF(D5="Дизайн-система","вне графа",IF(AND(K5=0,OR(D5="Состояние",D5="Служебная")),"демо / вход по событию",IF(K5=0,"⚠ сирота",IF(J5=0,"⚠ тупик","ок")))) | M5: Сверить | N5: Один экран кода на все случаи: регистрация, вход по SMS, вход сотрудника, восстановление пароля. Код в демо — 1234 · 25.09.2026: ожидаемое название приведено к схеме БД — одноразовые коды хранятся хешем (auth_codes)
A6: AUTH-03 | B6: AUTH | C6: Регистрация (имя, телефон, e-mail, пароль, согласия) | D6: Страница | E6: Клиент | H6: #/register · «Регистрация» | I6: Совпадает | J6: =COUNTIF(Связи!$C:$C,A6)+IF(G6="",0,COUNTIF(Навигация!$B:$B,G6)) | K6: =COUNTIF(Связи!$G:$G,A6)+COUNTIF(Навигация!$F:$F,A6) | L6: =IF(D6="Дизайн-система","вне графа",IF(AND(K6=0,OR(D6="Состояние",D6="Служебная")),"демо / вход по событию",IF(K6=0,"⚠ сирота",IF(J6=0,"⚠ тупик","ок")))) | M6: Сверить | N6: Порядок обратный карте: сначала регистрация (имя, телефон, e-mail, пароль, согласие на обработку ПДн), потом код AUTH-02 · 25.09.2026: ожидаемое название приведено к схеме БД — согласие на обработку ПДн с редакцией политики, согласие на новости (users.pd_consent_*, marketing_consent_at)
A7: AUTH-04 | B7: AUTH | C7: Вход сотрудника | D7: Страница | E7: Сотрудник | H7: #/staff/login · «Сотрудники · вход» | I7: Совпадает | J7: =COUNTIF(Связи!$C:$C,A7)+IF(G7="",0,COUNTIF(Навигация!$B:$B,G7)) | K7: =COUNTIF(Связи!$G:$G,A7)+COUNTIF(Навигация!$F:$F,A7) | L7: =IF(D7="Дизайн-система","вне графа",IF(AND(K7=0,OR(D7="Состояние",D7="Служебная")),"демо / вход по событию",IF(K7=0,"⚠ сирота",IF(J7=0,"⚠ тупик","ок")))) | M7: Точка входа сотрудников | N7: Вход только в раздел администратора
A8: AUTH-06 | B8: AUTH | C8: Восстановление пароля | D8: Страница | E8: Сотрудник | H8: #/forgot-password · «Забыли пароль» | I8: Совпадает | J8: =COUNTIF(Связи!$C:$C,A8)+IF(G8="",0,COUNTIF(Навигация!$B:$B,G8)) | K8: =COUNTIF(Связи!$G:$G,A8)+COUNTIF(Навигация!$F:$F,A8) | L8: =IF(D8="Дизайн-система","вне графа",IF(AND(K8=0,OR(D8="Состояние",D8="Служебная")),"демо / вход по событию",IF(K8=0,"⚠ сирота",IF(J8=0,"⚠ тупик","ок")))) | N8: Общий для клиента и сотрудника (запоминает, откуда пришли)
A9: BOOK-01 | B9: BOOK | C9: Шаг 1. Услуги (мультивыбор, корзина визита) | D9: Страница | E9: Клиент | G9: NAV-BOOK | H9: #/booking/services · «Запись · услуги» | I9: Совпадает | J9: =COUNTIF(Связи!$C:$C,A9)+IF(G9="",0,COUNTIF(Навигация!$B:$B,G9)) | K9: =COUNTIF(Связи!$G:$G,A9)+COUNTIF(Навигация!$F:$F,A9) | L9: =IF(D9="Дизайн-система","вне графа",IF(AND(K9=0,OR(D9="Состояние",D9="Служебная")),"демо / вход по событию",IF(K9=0,"⚠ сирота",IF(J9=0,"⚠ тупик","ок")))) | M9: Если вход из профиля мастера — мастер уже выбран | N9: Мультивыбор, поиск, категории, плашка корзины внизу. Если пришли от мастера — «Услуги мастера …»
A10: BOOK-02 | B10: BOOK | C10: Шаг 2. Мастер | D10: Страница | E10: Клиент | G10: NAV-BOOK | H10: #/booking/master · «Запись · мастер» | I10: Совпадает | J10: =COUNTIF(Связи!$C:$C,A10)+IF(G10="",0,COUNTIF(Навигация!$B:$B,G10)) | K10: =COUNTIF(Связи!$G:$G,A10)+COUNTIF(Навигация!$F:$F,A10) | L10: =IF(D10="Дизайн-система","вне графа",IF(AND(K10=0,OR(D10="Состояние",D10="Служебная")),"демо / вход по событию",IF(K10=0,"⚠ сирота",IF(J10=0,"⚠ тупик","ок")))) | N10: Есть «Любой свободный мастер» и блок «Не подходят для этого визита»
A11: BOOK-03 | B11: BOOK | C11: Шаг 3. Время | D11: Страница | E11: Клиент | G11: NAV-BOOK | H11: #/booking/time · «Запись · дата и время» | I11: Совпадает | J11: =COUNTIF(Связи!$C:$C,A11)+IF(G11="",0,COUNTIF(Навигация!$B:$B,G11)) | K11: =COUNTIF(Связи!$G:$G,A11)+COUNTIF(Навигация!$F:$F,A11) | L11: =IF(D11="Дизайн-система","вне графа",IF(AND(K11=0,OR(D11="Состояние",D11="Служебная")),"демо / вход по событию",IF(K11=0,"⚠ сирота",IF(J11=0,"⚠ тупик","ок")))) | M11: Есть вход в лист ожидания | N11: Лента дней + календарь на месяц, «Ближайшее свободное время», кнопка «Продолжить». Листа ожидания нет
A12: BOOK-04 | B12: BOOK | C12: Шаг 4. Подтверждение | D12: Страница | E12: Клиент | G12: NAV-BOOK | H12: #/booking/confirm · «Запись · подтверждение» | I12: Совпадает | J12: =COUNTIF(Связи!$C:$C,A12)+IF(G12="",0,COUNTIF(Навигация!$B:$B,G12)) | K12: =COUNTIF(Связи!$G:$G,A12)+COUNTIF(Навигация!$F:$F,A12) | L12: =IF(D12="Дизайн-система","вне графа",IF(AND(K12=0,OR(D12="Состояние",D12="Служебная")),"демо / вход по событию",IF(K12=0,"⚠ сирота",IF(J12=0,"⚠ тупик","ок")))) | N12: Удержание слота 10 минут, комментарий мастеру, «Оплата в студии»
A13: BOOK-05 | B13: BOOK | C13: Успех | D13: Страница | E13: Клиент | H13: #/booking/success · «Запись · успех» | I13: Совпадает | J13: =COUNTIF(Связи!$C:$C,A13)+IF(G13="",0,COUNTIF(Навигация!$B:$B,G13)) | K13: =COUNTIF(Связи!$G:$G,A13)+COUNTIF(Навигация!$F:$F,A13) | L13: =IF(D13="Дизайн-система","вне графа",IF(AND(K13=0,OR(D13="Состояние",D13="Служебная")),"демо / вход по событию",IF(K13=0,"⚠ сирота",IF(J13=0,"⚠ тупик","ок")))) | M13: Итоговый экран записи
A14: BOOK-06 | B14: BOOK | C14: Ошибка | D14: Страница | E14: Клиент | H14: #/booking/error · «Запись · ошибка» | I14: Совпадает | J14: =COUNTIF(Связи!$C:$C,A14)+IF(G14="",0,COUNTIF(Навигация!$B:$B,G14)) | K14: =COUNTIF(Связи!$G:$G,A14)+COUNTIF(Навигация!$F:$F,A14) | L14: =IF(D14="Дизайн-система","вне графа",IF(AND(K14=0,OR(D14="Состояние",D14="Служебная")),"демо / вход по событию",IF(K14=0,"⚠ сирота",IF(J14=0,"⚠ тупик","ок")))) | M14: Итоговый экран записи | N14: Сценарий «Ошибка сервера» в панели разработчика
A15: BOOK-M1 | B15: BOOK | C15: Слот занят | D15: Модалка | E15: Клиент | F15: BOOK-03 | H15: Модалка «Это время только что заняли» | I15: Совпадает | J15: =COUNTIF(Связи!$C:$C,A15)+IF(G15="",0,COUNTIF(Навигация!$B:$B,G15)) | K15: =COUNTIF(Связи!$G:$G,A15)+COUNTIF(Навигация!$F:$F,A15) | L15: =IF(D15="Дизайн-система","вне графа",IF(AND(K15=0,OR(D15="Состояние",D15="Служебная")),"демо / вход по событию",IF(K15=0,"⚠ сирота",IF(J15=0,"⚠ тупик","ок")))) | M15: Сверить: возможно, заменён листом ожидания | N15: Открывается с BOOK-04 при подтверждении (сценарий «Слот заняли»), а не с BOOK-03. Родитель — BOOK-04
A16: CAB-01 | B16: CAB | C16: Мои записи | D16: Страница | E16: Клиент | G16: NAV-CAB | H16: #/account · «Личный кабинет» (пункт меню «Мои записи») | I16: Совпадает | J16: =COUNTIF(Связи!$C:$C,A16)+IF(G16="",0,COUNTIF(Навигация!$B:$B,G16)) | K16: =COUNTIF(Связи!$G:$G,A16)+COUNTIF(Навигация!$F:$F,A16) | L16: =IF(D16="Дизайн-система","вне графа",IF(AND(K16=0,OR(D16="Состояние",D16="Служебная")),"демо / вход по событию",IF(K16=0,"⚠ сирота",IF(J16=0,"⚠ тупик","ок")))) | N16: Ближайшая запись с кнопками «Перенести»/«Отменить», остальные предстоящие, пустые состояния
A17: CAB-02 | B17: CAB | C17: История | D17: Страница | E17: Клиент | G17: NAV-CAB | H17: #/account/history · «Кабинет · история» | I17: Совпадает | J17: =COUNTIF(Связи!$C:$C,A17)+IF(G17="",0,COUNTIF(Навигация!$B:$B,G17)) | K17: =COUNTIF(Связи!$G:$G,A17)+COUNTIF(Навигация!$F:$F,A17) | L17: =IF(D17="Дизайн-система","вне графа",IF(AND(K17=0,OR(D17="Состояние",D17="Служебная")),"демо / вход по событию",IF(K17=0,"⚠ сирота",IF(J17=0,"⚠ тупик","ок")))) | N17: Фильтры, «Повторить», «Подробнее». Отзыва нет
A18: CAB-03 | B18: CAB | C18: Карточка записи | D18: Страница | E18: Клиент | G18: NAV-CAB | H18: #/account/bookings/:id · «Кабинет · запись» | I18: Совпадает | J18: =COUNTIF(Связи!$C:$C,A18)+IF(G18="",0,COUNTIF(Навигация!$B:$B,G18)) | K18: =COUNTIF(Связи!$G:$G,A18)+COUNTIF(Навигация!$F:$F,A18) | L18: =IF(D18="Дизайн-система","вне графа",IF(AND(K18=0,OR(D18="Состояние",D18="Служебная")),"демо / вход по событию",IF(K18=0,"⚠ сирота",IF(J18=0,"⚠ тупик","ок")))) | N18: Меньше 24 ч — кнопок нет, подсказка и «Позвонить в салон»
A19: CAB-04 | B19: CAB | C19: Перенос записи | D19: Страница | E19: Клиент | F19: CAB-03 | H19: #/account/bookings/:id/reschedule · «Кабинет · перенос записи» | I19: Совпадает | J19: =COUNTIF(Связи!$C:$C,A19)+IF(G19="",0,COUNTIF(Навигация!$B:$B,G19)) | K19: =COUNTIF(Связи!$G:$G,A19)+COUNTIF(Навигация!$F:$F,A19) | L19: =IF(D19="Дизайн-система","вне графа",IF(AND(K19=0,OR(D19="Состояние",D19="Служебная")),"демо / вход по событию",IF(K19=0,"⚠ сирота",IF(J19=0,"⚠ тупик","ок")))) | M19: Отдельная страница без меню кабинета | N19: Выбор времени → «Было → Стало» → «Запись перенесена»
A20: CAB-05 | B20: CAB | C20: Отмена записи | D20: Модалка | E20: Клиент | F20: CAB-03 | H20: Модалка «Отменить запись?» | I20: Совпадает | J20: =COUNTIF(Связи!$C:$C,A20)+IF(G20="",0,COUNTIF(Навигация!$B:$B,G20)) | K20: =COUNTIF(Связи!$G:$G,A20)+COUNTIF(Навигация!$F:$F,A20) | L20: =IF(D20="Дизайн-система","вне графа",IF(AND(K20=0,OR(D20="Состояние",D20="Служебная")),"демо / вход по событию",IF(K20=0,"⚠ сирота",IF(J20=0,"⚠ тупик","ок")))) | N20: Причина отмены, «Может, перенести?», экран «Запись отменена» внутри модалки. Открывается с CAB-01 и CAB-03
A21: CAB-07 | B21: CAB | C21: Профиль | D21: Страница | E21: Клиент | G21: NAV-CAB | H21: #/account/profile · «Кабинет · профиль» | I21: Совпадает | J21: =COUNTIF(Связи!$C:$C,A21)+IF(G21="",0,COUNTIF(Навигация!$B:$B,G21)) | K21: =COUNTIF(Связи!$G:$G,A21)+COUNTIF(Навигация!$F:$F,A21) | L21: =IF(D21="Дизайн-система","вне графа",IF(AND(K21=0,OR(D21="Состояние",D21="Служебная")),"демо / вход по событию",IF(K21=0,"⚠ сирота",IF(J21=0,"⚠ тупик","ок")))) | N21: Личные данные, смена пароля, «Выйти», «Удалить аккаунт»
A22: A-01 | B22: A | C22: Шахматка (день) | D22: Страница | E22: Администратор | G22: NAV-A | H22: #/staff/admin-home · «Администратор · Шахматка» | I22: Совпадает | J22: =COUNTIF(Связи!$C:$C,A22)+IF(G22="",0,COUNTIF(Навигация!$B:$B,G22)) | K22: =COUNTIF(Связи!$G:$G,A22)+COUNTIF(Навигация!$F:$F,A22) | L22: =IF(D22="Дизайн-система","вне графа",IF(AND(K22=0,OR(D22="Состояние",D22="Служебная")),"демо / вход по событию",IF(K22=0,"⚠ сирота",IF(J22=0,"⚠ тупик","ок")))) | M22: Главный экран администратора | N22: Четверг 24 сентября, сводка дня, колонки мастеров
A23: A-01w | B23: A | C23: Шахматка (неделя) | D23: Страница | E23: Администратор | F23: A-01 | G23: NAV-A | H23: Переключатель «Неделя» на #/staff/admin-home | I23: Совпадает | J23: =COUNTIF(Связи!$C:$C,A23)+IF(G23="",0,COUNTIF(Навигация!$B:$B,G23)) | K23: =COUNTIF(Связи!$G:$G,A23)+COUNTIF(Навигация!$F:$F,A23) | L23: =IF(D23="Дизайн-система","вне графа",IF(AND(K23=0,OR(D23="Состояние",D23="Служебная")),"демо / вход по событию",IF(K23=0,"⚠ сирота",IF(J23=0,"⚠ тупик","ок")))) | N23: Мастера × вт–сб (22–26 сентября). Четверг — живые записи с поповером, остальные дни — демо-записи и блокировки из паспорта. Добавлено 25.09.2026
A24: A-01d | B24: A | C24: Шахматка — перетаскивание записи | D24: Состояние | E24: Администратор | F24: A-01 | G24: NAV-A | H24: Перетаскивание записи в шахматке | I24: Совпадает | J24: =COUNTIF(Связи!$C:$C,A24)+IF(G24="",0,COUNTIF(Навигация!$B:$B,G24)) | K24: =COUNTIF(Связи!$G:$G,A24)+COUNTIF(Навигация!$F:$F,A24) | L24: =IF(D24="Дизайн-система","вне графа",IF(AND(K24=0,OR(D24="Состояние",D24="Служебная")),"демо / вход по событию",IF(K24=0,"⚠ сирота",IF(J24=0,"⚠ тупик","ок")))) | N24: Состояние внутри A-01
A25: A-02 | B25: A | C25: Панель создания записи | D25: Панель | E25: Администратор | F25: A-01 | H25: Панель «Новая запись» | I25: Совпадает | J25: =COUNTIF(Связи!$C:$C,A25)+IF(G25="",0,COUNTIF(Навигация!$B:$B,G25)) | K25: =COUNTIF(Связи!$G:$G,A25)+COUNTIF(Навигация!$F:$F,A25) | L25: =IF(D25="Дизайн-система","вне графа",IF(AND(K25=0,OR(D25="Состояние",D25="Служебная")),"демо / вход по событию",IF(K25=0,"⚠ сирота",IF(J25=0,"⚠ тупик","ок")))) | N25: Открывается с любого экрана администратора
A26: A-02s | B26: A | C26: Создание записи — конфликт слота | D26: Состояние | E26: Администратор | F26: A-02 | H26: Плашка «Слот только что занят другой записью» в панели | I26: Совпадает | J26: =COUNTIF(Связи!$C:$C,A26)+IF(G26="",0,COUNTIF(Навигация!$B:$B,G26)) | K26: =COUNTIF(Связи!$G:$G,A26)+COUNTIF(Навигация!$F:$F,A26) | L26: =IF(D26="Дизайн-система","вне графа",IF(AND(K26=0,OR(D26="Состояние",D26="Служебная")),"демо / вход по событию",IF(K26=0,"⚠ сирота",IF(J26=0,"⚠ тупик","ок"))))
A27: A-03 | B27: A | C27: Поповер записи | D27: Поповер | E27: Администратор | F27: A-01 | H27: Поповер записи | I27: Совпадает | J27: =COUNTIF(Связи!$C:$C,A27)+IF(G27="",0,COUNTIF(Навигация!$B:$B,G27)) | K27: =COUNTIF(Связи!$G:$G,A27)+COUNTIF(Навигация!$F:$F,A27) | L27: =IF(D27="Дизайн-система","вне графа",IF(AND(K27=0,OR(D27="Состояние",D27="Служебная")),"демо / вход по событию",IF(K27=0,"⚠ сирота",IF(J27=0,"⚠ тупик","ок")))) | N27: Кнопки: «Перенести», «Визит завершён», «Отметить неявку», «Отменить», «Открыть карточку клиента». «Подтвердить» и «Принять оплату» нет · 25.09.2026: у завершённой записи — «Фото работ» (A-12); время записи показывает уборку до … · 25.09.2026: «Визит завершён» и «Отметить неявку» — только для визита, который уже начался; у записей не из демо-дня в поповере показывается дата
A28: A-04 | B28: A | C28: Диалог переноса | D28: Модалка | E28: Администратор | F28: A-03 | H28: Диалог «Перенос записи» | I28: Совпадает | J28: =COUNTIF(Связи!$C:$C,A28)+IF(G28="",0,COUNTIF(Навигация!$B:$B,G28)) | K28: =COUNTIF(Связи!$G:$G,A28)+COUNTIF(Навигация!$F:$F,A28) | L28: =IF(D28="Дизайн-система","вне графа",IF(AND(K28=0,OR(D28="Состояние",D28="Служебная")),"демо / вход по событию",IF(K28=0,"⚠ сирота",IF(J28=0,"⚠ тупик","ок"))))
A29: A-05 | B29: A | C29: Диалог отмены | D29: Модалка | E29: Администратор | F29: A-03 | H29: Диалог «Отмена записи» | I29: Совпадает | J29: =COUNTIF(Связи!$C:$C,A29)+IF(G29="",0,COUNTIF(Навигация!$B:$B,G29)) | K29: =COUNTIF(Связи!$G:$G,A29)+COUNTIF(Навигация!$F:$F,A29) | L29: =IF(D29="Дизайн-система","вне графа",IF(AND(K29=0,OR(D29="Состояние",D29="Служебная")),"демо / вход по событию",IF(K29=0,"⚠ сирота",IF(J29=0,"⚠ тупик","ок"))))
A30: A-06 | B30: A | C30: Диалог неявки | D30: Модалка | E30: Администратор | F30: A-03 | H30: Диалог «Неявка клиента» | I30: Совпадает | J30: =COUNTIF(Связи!$C:$C,A30)+IF(G30="",0,COUNTIF(Навигация!$B:$B,G30)) | K30: =COUNTIF(Связи!$G:$G,A30)+COUNTIF(Навигация!$F:$F,A30) | L30: =IF(D30="Дизайн-система","вне графа",IF(AND(K30=0,OR(D30="Состояние",D30="Служебная")),"демо / вход по событию",IF(K30=0,"⚠ сирота",IF(J30=0,"⚠ тупик","ок"))))
A31: A-07 | B31: A | C31: Клиенты (список) | D31: Страница | E31: Администратор | G31: NAV-A | H31: #/staff/admin/clients · «Администратор · Клиенты» | I31: Совпадает | J31: =COUNTIF(Связи!$C:$C,A31)+IF(G31="",0,COUNTIF(Навигация!$B:$B,G31)) | K31: =COUNTIF(Связи!$G:$G,A31)+COUNTIF(Навигация!$F:$F,A31) | L31: =IF(D31="Дизайн-система","вне графа",IF(AND(K31=0,OR(D31="Состояние",D31="Служебная")),"демо / вход по событию",IF(K31=0,"⚠ сирота",IF(J31=0,"⚠ тупик","ок")))) | N31: Поиск, фильтры, сортировка, чекбоксы (массовых действий нет), пагинация
A32: A-08 | B32: A | C32: Быстрый просмотр клиента | D32: Панель | E32: Администратор | F32: A-07 | H32: Панель быстрого просмотра клиента | I32: Совпадает | J32: =COUNTIF(Связи!$C:$C,A32)+IF(G32="",0,COUNTIF(Навигация!$B:$B,G32)) | K32: =COUNTIF(Связи!$G:$G,A32)+COUNTIF(Навигация!$F:$F,A32) | L32: =IF(D32="Дизайн-система","вне графа",IF(AND(K32=0,OR(D32="Состояние",D32="Служебная")),"демо / вход по событию",IF(K32=0,"⚠ сирота",IF(J32=0,"⚠ тупик","ок"))))
A33: A-09 | B33: A | C33: Карточка клиента (полная) | D33: Страница | E33: Администратор | F33: A-07 | G33: NAV-A | H33: #/staff/admin/client/:id · «Администратор · карточка клиента» | I33: Совпадает | J33: =COUNTIF(Связи!$C:$C,A33)+IF(G33="",0,COUNTIF(Навигация!$B:$B,G33)) | K33: =COUNTIF(Связи!$G:$G,A33)+COUNTIF(Навигация!$F:$F,A33) | L33: =IF(D33="Дизайн-система","вне графа",IF(AND(K33=0,OR(D33="Состояние",D33="Служебная")),"демо / вход по событию",IF(K33=0,"⚠ сирота",IF(J33=0,"⚠ тупик","ок")))) | N33: Вкладки: история, предстоящие, заметки, важное. «Написать» нет. «Архивировать» убрана 25.09.2026: архива клиентов нет в паспорте, записи и история не удаляются · 25.09.2026: в истории визитов — «N фото» / «+ Добавить фото» (A-12) · 25.09.2026: предстоящие записи кликабельны и открывают поповер записи A-03
A34: A-11 | B34: A | C34: В чёрный список | D34: Модалка | E34: Администратор | F34: A-09 | H34: Диалог «Добавить в чёрный список» | I34: Совпадает | J34: =COUNTIF(Связи!$C:$C,A34)+IF(G34="",0,COUNTIF(Навигация!$B:$B,G34)) | K34: =COUNTIF(Связи!$G:$G,A34)+COUNTIF(Навигация!$F:$F,A34) | L34: =IF(D34="Дизайн-система","вне графа",IF(AND(K34=0,OR(D34="Состояние",D34="Служебная")),"демо / вход по событию",IF(K34=0,"⚠ сирота",IF(J34=0,"⚠ тупик","ок"))))
A35: A-19 | B35: A | C35: Мастера (список) | D35: Страница | E35: Администратор | G35: NAV-A | H35: #/staff/admin/masters · «Администратор · Мастера» | I35: Совпадает | J35: =COUNTIF(Связи!$C:$C,A35)+IF(G35="",0,COUNTIF(Навигация!$B:$B,G35)) | K35: =COUNTIF(Связи!$G:$G,A35)+COUNTIF(Навигация!$F:$F,A35) | L35: =IF(D35="Дизайн-система","вне графа",IF(AND(K35=0,OR(D35="Состояние",D35="Служебная")),"демо / вход по событию",IF(K35=0,"⚠ сирота",IF(J35=0,"⚠ тупик","ок")))) | N35: Вкладок нет: кнопка «График смен на месяц»
A36: A-20 | B36: A | C36: График смен | D36: Страница | E36: Администратор | F36: A-19 | G36: NAV-A | H36: #/staff/admin/masters/schedule · «Администратор · График смен» | I36: Совпадает | J36: =COUNTIF(Связи!$C:$C,A36)+IF(G36="",0,COUNTIF(Навигация!$B:$B,G36)) | K36: =COUNTIF(Связи!$G:$G,A36)+COUNTIF(Навигация!$F:$F,A36) | L36: =IF(D36="Дизайн-система","вне графа",IF(AND(K36=0,OR(D36="Состояние",D36="Служебная")),"демо / вход по событию",IF(K36=0,"⚠ сирота",IF(J36=0,"⚠ тупик","ок")))) | N36: Клик по ячейке — рабочий день / выходной · 25.09.2026: под сеткой — блок «Особые дни студии» (A-20d), особые дни отмечены рамкой
A37: A-22 | B37: A | C37: Карточка мастера | D37: Страница | E37: Администратор | F37: A-19 | G37: NAV-A | H37: #/staff/admin/masters/:id · «Администратор · карточка мастера» | I37: Совпадает | J37: =COUNTIF(Связи!$C:$C,A37)+IF(G37="",0,COUNTIF(Навигация!$B:$B,G37)) | K37: =COUNTIF(Связи!$G:$G,A37)+COUNTIF(Навигация!$F:$F,A37) | L37: =IF(D37="Дизайн-система","вне графа",IF(AND(K37=0,OR(D37="Состояние",D37="Служебная")),"демо / вход по событию",IF(K37=0,"⚠ сирота",IF(J37=0,"⚠ тупик","ок")))) | N37: Имя, статус, специализация; переключатель уровня «Мастер / Топ-мастер» и цены услуг по уровню (masters.level); рабочие дни и часы; форма «Новый график с даты» (A-22p, master_weekly_hours.valid_from). Обновлено 25.09.2026 при сверке со схемой БД
A38: A-23 | B38: A | C38: Услуги (список) | D38: Страница | E38: Администратор | G38: NAV-A | H38: #/staff/admin/services · «Администратор · Услуги» | I38: Совпадает | J38: =COUNTIF(Связи!$C:$C,A38)+IF(G38="",0,COUNTIF(Навигация!$B:$B,G38)) | K38: =COUNTIF(Связи!$G:$G,A38)+COUNTIF(Навигация!$F:$F,A38) | L38: =IF(D38="Дизайн-система","вне графа",IF(AND(K38=0,OR(D38="Состояние",D38="Служебная")),"демо / вход по событию",IF(K38=0,"⚠ сирота",IF(J38=0,"⚠ тупик","ок")))) | N38: По категориям, «+ Категория», «+ Добавить услугу»
A39: A-24 | B39: A | C39: Форма услуги | D39: Страница | E39: Администратор | F39: A-23 | G39: NAV-A | H39: #/staff/admin/services/form · «Администратор · форма услуги» | I39: Совпадает | J39: =COUNTIF(Связи!$C:$C,A39)+IF(G39="",0,COUNTIF(Навигация!$B:$B,G39)) | K39: =COUNTIF(Связи!$G:$G,A39)+COUNTIF(Навигация!$F:$F,A39) | L39: =IF(D39="Дизайн-система","вне графа",IF(AND(K39=0,OR(D39="Состояние",D39="Служебная")),"демо / вход по событию",IF(K39=0,"⚠ сирота",IF(J39=0,"⚠ тупик","ок")))) | N39: Открывается из списка (строка услуги, «+ Добавить услугу») и по прямому адресу; «Сохранить», «Отмена», «← Услуги» возвращают к списку. Исправлено 25.09.2026 · 25.09.2026: добавлены поля «Уборка после услуги, мин» и «Цена у топ-мастера, ₽» с проверкой «не ниже цены у мастера»
A40: A-S1 | B40: A | C40: Запись изменена другим сотрудником | D40: Состояние | E40: Администратор | F40: A-01 | H40: Галерея состояний · «Конфликт одновременного редактирования» | I40: Совпадает | J40: =COUNTIF(Связи!$C:$C,A40)+IF(G40="",0,COUNTIF(Навигация!$B:$B,G40)) | K40: =COUNTIF(Связи!$G:$G,A40)+COUNTIF(Навигация!$F:$F,A40) | L40: =IF(D40="Дизайн-система","вне графа",IF(AND(K40=0,OR(D40="Состояние",D40="Служебная")),"демо / вход по событию",IF(K40=0,"⚠ сирота",IF(J40=0,"⚠ тупик","ок")))) | N40: Только карточка в галерее A-33
...

Sheet Навигация
A1: ID | B1: Набор | C1: Элемент | D1: Пункт | E1: Действие | F1: Куда (ID) | G1: Куда (название) | H1: Где стоит | I1: Примечание | J1: Статус | K1: Факт в прототипе
A2: N-01 | B2: NAV-LAND | C2: Шапка лендинга | D2: Логотип | E2: Якорь | F2: ANCHOR | G2: =IF(F2="","⚠ не определено",IF(F2="ANCHOR","Прокрутка к секции",IF(F2="EXT","Внешняя ссылка",IF(F2="PARENT","Вернуться туда, откуда открыто",IFERROR(INDEX(Реестр!$C:$C,MATCH(F2,Реестр!$A:$A,0)),"⚠ нет в реестре"))))) | H2: PUB-01, PUB-05 | I2: С профиля мастера — переход на PUB-01 | J2: Связано | K2: Лендинг: прокрутка наверх. PUB-05: логотип ведёт на лендинг
A3: N-02 | B3: NAV-LAND | C3: Шапка лендинга | D3: Услуги | E3: Якорь | F3: ANCHOR | G3: =IF(F3="","⚠ не определено",IF(F3="ANCHOR","Прокрутка к секции",IF(F3="EXT","Внешняя ссылка",IF(F3="PARENT","Вернуться туда, откуда открыто",IFERROR(INDEX(Реестр!$C:$C,MATCH(F3,Реестр!$A:$A,0)),"⚠ нет в реестре"))))) | H3: PUB-01, PUB-05 | I3: С PUB-05 — переход на PUB-01 к секции | J3: Связано | K3: Есть на лендинге. На PUB-05 шапки с якорями нет
A4: N-03 | B4: NAV-LAND | C4: Шапка лендинга | D4: Как это работает | E4: Якорь | F4: ANCHOR | G4: =IF(F4="","⚠ не определено",IF(F4="ANCHOR","Прокрутка к секции",IF(F4="EXT","Внешняя ссылка",IF(F4="PARENT","Вернуться туда, откуда открыто",IFERROR(INDEX(Реестр!$C:$C,MATCH(F4,Реестр!$A:$A,0)),"⚠ нет в реестре"))))) | H4: PUB-01, PUB-05 | J4: Связано | K4: Есть на лендинге. На PUB-05 нет
A5: N-04 | B5: NAV-LAND | C5: Шапка лендинга | D5: Мастера | E5: Якорь | F5: ANCHOR | G5: =IF(F5="","⚠ не определено",IF(F5="ANCHOR","Прокрутка к секции",IF(F5="EXT","Внешняя ссылка",IF(F5="PARENT","Вернуться туда, откуда открыто",IFERROR(INDEX(Реестр!$C:$C,MATCH(F5,Реестр!$A:$A,0)),"⚠ нет в реестре"))))) | H5: PUB-01, PUB-05 | J5: Связано | K5: Есть на лендинге. На PUB-05 нет
A6: N-05 | B6: NAV-LAND | C6: Шапка лендинга | D6: Работы | E6: Якорь | F6: ANCHOR | G6: =IF(F6="","⚠ не определено",IF(F6="ANCHOR","Прокрутка к секции",IF(F6="EXT","Внешняя ссылка",IF(F6="PARENT","Вернуться туда, откуда открыто",IFERROR(INDEX(Реестр!$C:$C,MATCH(F6,Реестр!$A:$A,0)),"⚠ нет в реестре"))))) | H6: PUB-01, PUB-05 | J6: Связано | K6: Есть на лендинге. На PUB-05 нет
A7: N-06 | B7: NAV-LAND | C7: Шапка лендинга | D7: Контакты | E7: Якорь | F7: ANCHOR | G7: =IF(F7="","⚠ не определено",IF(F7="ANCHOR","Прокрутка к секции",IF(F7="EXT","Внешняя ссылка",IF(F7="PARENT","Вернуться туда, откуда открыто",IFERROR(INDEX(Реестр!$C:$C,MATCH(F7,Реестр!$A:$A,0)),"⚠ нет в реестре"))))) | H7: PUB-01, PUB-05 | J7: Связано | K7: Есть на лендинге. На PUB-05 нет
A8: N-07 | B8: NAV-LAND | C8: Шапка лендинга | D8: Записаться | E8: Переход | F8: BOOK-01 | G8: =IF(F8="","⚠ не определено",IF(F8="ANCHOR","Прокрутка к секции",IF(F8="EXT","Внешняя ссылка",IF(F8="PARENT","Вернуться туда, откуда открыто",IFERROR(INDEX(Реестр!$C:$C,MATCH(F8,Реестр!$A:$A,0)),"⚠ нет в реестре"))))) | H8: PUB-01, PUB-05 | J8: Нет элемента | K8: В шапке «Записаться» нет. «Записаться онлайн» — в первом экране и финальном призыве
A9: N-08 | B9: NAV-LAND | C9: Шапка лендинга | D9: Войти | E9: Переход | F9: AUTH-01 | G9: =IF(F9="","⚠ не определено",IF(F9="ANCHOR","Прокрутка к секции",IF(F9="EXT","Внешняя ссылка",IF(F9="PARENT","Вернуться туда, откуда открыто",IFERROR(INDEX(Реестр!$C:$C,MATCH(F9,Реестр!$A:$A,0)),"⚠ нет в реестре"))))) | H9: PUB-01, PUB-05 | I9: Для неавторизованного | J9: Связано | K9: «Войти» → #/login
A10: N-09 | B10: NAV-LAND | C10: Меню аккаунта в шапке | D10: Мои записи | E10: Переход | F10: CAB-01 | G10: =IF(F10="","⚠ не определено",IF(F10="ANCHOR","Прокрутка к секции",IF(F10="EXT","Внешняя ссылка",IF(F10="PARENT","Вернуться туда, откуда открыто",IFERROR(INDEX(Реестр!$C:$C,MATCH(F10,Реестр!$A:$A,0)),"⚠ нет в реестре"))))) | H10: PUB-01, PUB-05 | I10: Выпадающее меню авторизованного | J10: Связано | K10: → #/account
A11: N-10 | B11: NAV-LAND | C11: Меню аккаунта в шапке | D11: Профиль | E11: Переход | F11: CAB-07 | G11: =IF(F11="","⚠ не определено",IF(F11="ANCHOR","Прокрутка к секции",IF(F11="EXT","Внешняя ссылка",IF(F11="PARENT","Вернуться туда, откуда открыто",IFERROR(INDEX(Реестр!$C:$C,MATCH(F11,Реестр!$A:$A,0)),"⚠ нет в реестре"))))) | H11: PUB-01, PUB-05 | J11: Связано | K11: → #/account/profile
A12: N-11 | B12: NAV-LAND | C12: Меню аккаунта в шапке | D12: Выйти | E12: Переход | F12: PUB-01 | G12: =IF(F12="","⚠ не определено",IF(F12="ANCHOR","Прокрутка к секции",IF(F12="EXT","Внешняя ссылка",IF(F12="PARENT","Вернуться туда, откуда открыто",IFERROR(INDEX(Реестр!$C:$C,MATCH(F12,Реестр!$A:$A,0)),"⚠ нет в реестре"))))) | H12: PUB-01, PUB-05 | J12: Связано | K12: Разлогинивает и остаётся на лендинге
A13: N-12 | B13: NAV-LAND | C13: Подвал лендинга | D13: Ссылки на секции | E13: Якорь | F13: ANCHOR | G13: =IF(F13="","⚠ не определено",IF(F13="ANCHOR","Прокрутка к секции",IF(F13="EXT","Внешняя ссылка",IF(F13="PARENT","Вернуться туда, откуда открыто",IFERROR(INDEX(Реестр!$C:$C,MATCH(F13,Реестр!$A:$A,0)),"⚠ нет в реестре"))))) | H13: PUB-01, PUB-05 | J13: Связано | K13: Услуги, Мастера, Работы, Контакты
A14: N-13 | B14: NAV-LAND | C14: Подвал лендинга | D14: Телефон, соцсети, карта | E14: Внешняя ссылка | F14: EXT | G14: =IF(F14="","⚠ не определено",IF(F14="ANCHOR","Прокрутка к секции",IF(F14="EXT","Внешняя ссылка",IF(F14="PARENT","Вернуться туда, откуда открыто",IFERROR(INDEX(Реестр!$C:$C,MATCH(F14,Реестр!$A:$A,0)),"⚠ нет в реестре"))))) | H14: PUB-01, PUB-05 | I14: 25.09.2026: данные есть: settings.phone, map_url, vk_url, telegram_url. Нужно сделать ссылки в подвале лендинга | J14: Связано | K14: В подвале: адрес → карта, телефон → tel:, VK и Telegram → ссылки. В секции «Контакты» то же, карта-заглушка стала ссылкой «Открыть на карте». Сделано 25.09.2026
A15: N-14 | B15: NAV-LAND | C15: Подвал лендинга | D15: Вход для сотрудников | E15: Переход | F15: AUTH-04 | G15: =IF(F15="","⚠ не определено",IF(F15="ANCHOR","Прокрутка к секции",IF(F15="EXT","Внешняя ссылка",IF(F15="PARENT","Вернуться туда, откуда открыто",IFERROR(INDEX(Реестр!$C:$C,MATCH(F15,Реестр!$A:$A,0)),"⚠ нет в реестре"))))) | H15: PUB-01 | J15: Связано | K15: Ссылка в подвале лендинга рядом с политикой ПДн. Добавлено 25.09.2026
A16: N-15 | B16: NAV-BOOK | C16: Индикатор шагов | D16: Услуги | E16: Переход | F16: BOOK-01 | G16: =IF(F16="","⚠ не определено",IF(F16="ANCHOR","Прокрутка к секции",IF(F16="EXT","Внешняя ссылка",IF(F16="PARENT","Вернуться туда, откуда открыто",IFERROR(INDEX(Реестр!$C:$C,MATCH(F16,Реестр!$A:$A,0)),"⚠ нет в реестре"))))) | H16: BOOK-01…BOOK-04 | I16: Возврат к пройденному шагу | J16: Связано
A17: N-16 | B17: NAV-BOOK | C17: Индикатор шагов | D17: Мастер | E17: Переход | F17: BOOK-02 | G17: =IF(F17="","⚠ не определено",IF(F17="ANCHOR","Прокрутка к секции",IF(F17="EXT","Внешняя ссылка",IF(F17="PARENT","Вернуться туда, откуда открыто",IFERROR(INDEX(Реестр!$C:$C,MATCH(F17,Реестр!$A:$A,0)),"⚠ нет в реестре"))))) | H17: BOOK-01…BOOK-04 | J17: Связано
A18: N-17 | B18: NAV-BOOK | C18: Индикатор шагов | D18: Время | E18: Переход | F18: BOOK-03 | G18: =IF(F18="","⚠ не определено",IF(F18="ANCHOR","Прокрутка к секции",IF(F18="EXT","Внешняя ссылка",IF(F18="PARENT","Вернуться туда, откуда открыто",IFERROR(INDEX(Реестр!$C:$C,MATCH(F18,Реестр!$A:$A,0)),"⚠ нет в реестре"))))) | H18: BOOK-01…BOOK-04 | J18: Связано
A19: N-18 | B19: NAV-BOOK | C19: Индикатор шагов | D19: Подтверждение | E19: Переход | F19: BOOK-04 | G19: =IF(F19="","⚠ не определено",IF(F19="ANCHOR","Прокрутка к секции",IF(F19="EXT","Внешняя ссылка",IF(F19="PARENT","Вернуться туда, откуда открыто",IFERROR(INDEX(Реестр!$C:$C,MATCH(F19,Реестр!$A:$A,0)),"⚠ нет в реестре"))))) | H19: BOOK-01…BOOK-04 | J19: Нет элемента | K19: Пункт «Подтверждение» некликабельный (последний шаг)
A20: N-19 | B20: NAV-BOOK | C20: Шапка записи | D20: Логотип / выход из записи | E20: Переход | F20: PUB-01 | G20: =IF(F20="","⚠ не определено",IF(F20="ANCHOR","Прокрутка к секции",IF(F20="EXT","Внешняя ссылка",IF(F20="PARENT","Вернуться туда, откуда открыто",IFERROR(INDEX(Реестр!$C:$C,MATCH(F20,Реестр!$A:$A,0)),"⚠ нет в реестре"))))) | H20: BOOK-01…BOOK-04 | J20: Связано | K20: Через модалку «Выйти из записи?» (BOOK-M6) → лендинг
A21: N-20 | B21: NAV-CAB | C21: Меню кабинета | D21: Мои записи | E21: Переход | F21: CAB-01 | G21: =IF(F21="","⚠ не определено",IF(F21="ANCHOR","Прокрутка к секции",IF(F21="EXT","Внешняя ссылка",IF(F21="PARENT","Вернуться туда, откуда открыто",IFERROR(INDEX(Реестр!$C:$C,MATCH(F21,Реестр!$A:$A,0)),"⚠ нет в реестре"))))) | H21: Все страницы CAB с меню | I21: Сайдбар на десктопе, нижняя панель на мобильном | J21: Связано | K21: Сайдбар на десктопе, нижняя панель на мобильном
A22: N-21 | B22: NAV-CAB | C22: Меню кабинета | D22: История | E22: Переход | F22: CAB-02 | G22: =IF(F22="","⚠ не определено",IF(F22="ANCHOR","Прокрутка к секции",IF(F22="EXT","Внешняя ссылка",IF(F22="PARENT","Вернуться туда, откуда открыто",IFERROR(INDEX(Реестр!$C:$C,MATCH(F22,Реестр!$A:$A,0)),"⚠ нет в реестре"))))) | H22: Все страницы CAB с меню | J22: Связано
A23: N-23 | B23: NAV-CAB | C23: Меню кабинета | D23: Профиль | E23: Переход | F23: CAB-07 | G23: =IF(F23="","⚠ не определено",IF(F23="ANCHOR","Прокрутка к секции",IF(F23="EXT","Внешняя ссылка",IF(F23="PARENT","Вернуться туда, откуда открыто",IFERROR(INDEX(Реестр!$C:$C,MATCH(F23,Реестр!$A:$A,0)),"⚠ нет в реестре"))))) | H23: Все страницы CAB с меню | J23: Связано
A24: N-25 | B24: NAV-CAB | C24: Шапка кабинета | D24: Логотип / на лендинг | E24: Переход | F24: PUB-01 | G24: =IF(F24="","⚠ не определено",IF(F24="ANCHOR","Прокрутка к секции",IF(F24="EXT","Внешняя ссылка",IF(F24="PARENT","Вернуться туда, откуда открыто",IFERROR(INDEX(Реестр!$C:$C,MATCH(F24,Реестр!$A:$A,0)),"⚠ нет в реестре"))))) | H24: Все страницы CAB с меню | J24: Нет элемента | K24: Шапки кабинета с логотипом нет
A25: N-26 | B25: NAV-CAB | C25: Шапка кабинета | D25: Записаться | E25: Переход | F25: BOOK-01 | G25: =IF(F25="","⚠ не определено",IF(F25="ANCHOR","Прокрутка к секции",IF(F25="EXT","Внешняя ссылка",IF(F25="PARENT","Вернуться туда, откуда открыто",IFERROR(INDEX(Реестр!$C:$C,MATCH(F25,Реестр!$A:$A,0)),"⚠ нет в реестре"))))) | H25: Все страницы CAB с меню | I25: Сверить наличие | J25: Нет элемента | K25: В шапке нет; кнопка «Новая запись» / «Записаться» — в содержимом CAB-01
A26: N-27 | B26: NAV-CAB | C26: Шапка кабинета | D26: Выйти | E26: Переход | F26: PUB-01 | G26: =IF(F26="","⚠ не определено",IF(F26="ANCHOR","Прокрутка к секции",IF(F26="EXT","Внешняя ссылка",IF(F26="PARENT","Вернуться туда, откуда открыто",IFERROR(INDEX(Реестр!$C:$C,MATCH(F26,Реестр!$A:$A,0)),"⚠ нет в реестре"))))) | H26: Все страницы CAB с меню | J26: Связано | K26: «Выйти» в сайдбаре (на мобильном — в профиле) → лендинг
A27: N-35 | B27: NAV-M | C27: Переключатель ролей | D27: Администратор | E27: Переход | F27: A-01 | G27: =IF(F27="","⚠ не определено",IF(F27="ANCHOR","Прокрутка к секции",IF(F27="EXT","Внешняя ссылка",IF(F27="PARENT","Вернуться туда, откуда открыто",IFERROR(INDEX(Реестр!$C:$C,MATCH(F27,Реестр!$A:$A,0)),"⚠ нет в реестре"))))) | H27: Все страницы M | I27: 25.09.2026: кабинета мастера нет ни в паспорте, ни в схеме БД (у мастеров нет учетных записей) | J27: Не нужно | K27: Кабинета мастера в прототипе нет (по паспорту у мастеров нет кабинета)
A28: N-36 | B28: NAV-M | C28: Переключатель ролей | D28: Выход | E28: Переход | F28: AUTH-04 | G28: =IF(F28="","⚠ не определено",IF(F28="ANCHOR","Прокрутка к секции",IF(F28="EXT","Внешняя ссылка",IF(F28="PARENT","Вернуться туда, откуда открыто",IFERROR(INDEX(Реестр!$C:$C,MATCH(F28,Реестр!$A:$A,0)),"⚠ нет в реестре"))))) | H28: Все страницы M | I28: 25.09.2026: кабинета мастера нет ни в паспорте, ни в схеме БД (у мастеров нет учетных записей) | J28: Не нужно | K28: Кабинета мастера в прототипе нет (по паспорту у мастеров нет кабинета)
A29: N-37 | B29: NAV-A | C29: Боковое меню | D29: Расписание | E29: Переход | F29: A-01 | G29: =IF(F29="","⚠ не определено",IF(F29="ANCHOR","Прокрутка к секции",IF(F29="EXT","Внешняя ссылка",IF(F29="PARENT","Вернуться туда, откуда открыто",IFERROR(INDEX(Реестр!$C:$C,MATCH(F29,Реестр!$A:$A,0)),"⚠ нет в реестре"))))) | H29: Все страницы A с меню | J29: Связано | K29: Иконка «Расписание»
A30: N-38 | B30: NAV-A | C30: Боковое меню | D30: Клиенты | E30: Переход | F30: A-07 | G30: =IF(F30="","⚠ не определено",IF(F30="ANCHOR","Прокрутка к секции",IF(F30="EXT","Внешняя ссылка",IF(F30="PARENT","Вернуться туда, откуда открыто",IFERROR(INDEX(Реестр!$C:$C,MATCH(F30,Реестр!$A:$A,0)),"⚠ нет в реестре"))))) | H30: Все страницы A с меню | J30: Связано | K30: Иконка «Клиенты»
A31: N-41 | B31: NAV-A | C31: Боковое меню | D31: Мастера | E31: Переход | F31: A-19 | G31: =IF(F31="","⚠ не определено",IF(F31="ANCHOR","Прокрутка к секции",IF(F31="EXT","Внешняя ссылка",IF(F31="PARENT","Вернуться туда, откуда открыто",IFERROR(INDEX(Реестр!$C:$C,MATCH(F31,Реестр!$A:$A,0)),"⚠ нет в реестре"))))) | H31: Все страницы A с меню | J31: Связано | K31: Иконка «Мастера»
A32: N-42 | B32: NAV-A | C32: Боковое меню | D32: Услуги | E32: Переход | F32: A-23 | G32: =IF(F32="","⚠ не определено",IF(F32="ANCHOR","Прокрутка к секции",IF(F32="EXT","Внешняя ссылка",IF(F32="PARENT","Вернуться туда, откуда открыто",IFERROR(INDEX(Реестр!$C:$C,MATCH(F32,Реестр!$A:$A,0)),"⚠ нет в реестре"))))) | H32: Все страницы A с меню | J32: Связано | K32: Иконка «Услуги»
A33: N-48 | B33: NAV-A | C33: Шапка администратора | D33: Новая запись | E33: Панель | F33: A-02 | G33: =IF(F33="","⚠ не определено",IF(F33="ANCHOR","Прокрутка к секции",IF(F33="EXT","Внешняя ссылка",IF(F33="PARENT","Вернуться туда, откуда открыто",IFERROR(INDEX(Реестр!$C:$C,MATCH(F33,Реестр!$A:$A,0)),"⚠ нет в реестре"))))) | H33: Все страницы A с меню | J33: Связано | K33: «+ Новая запись» — только в шапке шахматки A-01
A34: N-49 | B34: NAV-A | C34: Шапка администратора | D34: Результат поиска клиента | E34: Панель | F34: A-08 | G34: =IF(F34="","⚠ не определено",IF(F34="ANCHOR","Прокрутка к секции",IF(F34="EXT","Внешняя ссылка",IF(F34="PARENT","Вернуться туда, откуда открыто",IFERROR(INDEX(Реестр!$C:$C,MATCH(F34,Реестр!$A:$A,0)),"⚠ нет в реестре"))))) | H34: Все страницы A с меню | I34: 25.09.2026: данные есть: поиск клиентов по имени и телефону (users). Нужно открыть панель A-08 по результату поиска | J34: Связано | K34: Поиск по имени или телефону показывает список клиентов; клик открывает панель клиента A-08. Сделано 25.09.2026
A35: N-53 | B35: NAV-A | C35: Переключатель ролей | D35: Выход | E35: Переход | F35: AUTH-04 | G35: =IF(F35="","⚠ не определено",IF(F35="ANCHOR","Прокрутка к секции",IF(F35="EXT","Внешняя ссылка",IF(F35="PARENT","Вернуться туда, откуда открыто",IFERROR(INDEX(Реестр!$C:$C,MATCH(F35,Реестр!$A:$A,0)),"⚠ нет в реестре"))))) | H35: Все страницы A с меню | J35: Связано | K35: Меню «Администратор ▾» → «Выход» → #/staff/login (только на A-01)
A36: N-54 | B36: NAV-LAND | C36: Шапка лендинга | D36: Регистрация | E36: Переход | F36: AUTH-03 | G36: =IF(F36="","⚠ не определено",IF(F36="ANCHOR","Прокрутка к секции",IF(F36="EXT","Внешняя ссылка",IF(F36="PARENT","Вернуться туда, откуда открыто",IFERROR(INDEX(Реестр!$C:$C,MATCH(F36,Реестр!$A:$A,0)),"⚠ нет в реестре"))))) | H36: PUB-01 | I36: Для неавторизованного | J36: Связано | K36: Есть в прототипе, не было в карте
A37: N-55 | B37: NAV-BOOK | C37: Шапка записи | D37: ← Назад | E37: Назад | F37: PARENT | G37: =IF(F37="","⚠ не определено",IF(F37="ANCHOR","Прокрутка к секции",IF(F37="EXT","Внешняя ссылка",IF(F37="PARENT","Вернуться туда, откуда открыто",IFERROR(INDEX(Реестр!$C:$C,MATCH(F37,Реестр!$A:$A,0)),"⚠ нет в реестре"))))) | H37: BOOK-01…BOOK-04 | I37: Шаг назад; на шаге услуг — модалка BOOK-M6 | J37: Связано | K37: Есть в прототипе, не было в карте

Sheet Связи
A1: ID | B1: Блок | C1: Откуда (ID) | D1: Откуда (название) | E1: Элемент | F1: Действие | G1: Куда (ID) | H1: Куда (название) | I1: Примечание | J1: Статус | K1: Факт в прототипе
A2: L-001 | B2: PUB | C2: PUB-01 | D2: =IFERROR(INDEX(Реестр!$C:$C,MATCH(C2,Реестр!$A:$A,0)),"⚠ нет в реестре") | E2: Кнопка «Записаться» в первом экране | F2: Переход | G2: BOOK-01 | H2: =IF(G2="ANCHOR","Прокрутка к секции",IF(G2="EXT","Внешняя ссылка",IF(G2="PARENT","Вернуться туда, откуда открыто",IFERROR(INDEX(Реестр!$C:$C,MATCH(G2,Реестр!$A:$A,0)),"⚠ нет в реестре")))) | J2: Связано | K2: «Записаться онлайн»
A3: L-002 | B3: PUB | C3: PUB-01 | D3: =IFERROR(INDEX(Реестр!$C:$C,MATCH(C3,Реестр!$A:$A,0)),"⚠ нет в реестре") | E3: Кнопка «Записаться» в финальном призыве | F3: Переход | G3: BOOK-01 | H3: =IF(G3="ANCHOR","Прокрутка к секции",IF(G3="EXT","Внешняя ссылка",IF(G3="PARENT","Вернуться туда, откуда открыто",IFERROR(INDEX(Реестр!$C:$C,MATCH(G3,Реестр!$A:$A,0)),"⚠ нет в реестре")))) | J3: Связано | K3: «Записаться онлайн»
A4: L-003 | B4: PUB | C4: PUB-01 | D4: =IFERROR(INDEX(Реестр!$C:$C,MATCH(C4,Реестр!$A:$A,0)),"⚠ нет в реестре") | E4: Карточка услуги в секции «Услуги» | F4: Переход | G4: BOOK-01 | H4: =IF(G4="ANCHOR","Прокрутка к секции",IF(G4="EXT","Внешняя ссылка",IF(G4="PARENT","Вернуться туда, откуда открыто",IFERROR(INDEX(Реестр!$C:$C,MATCH(G4,Реестр!$A:$A,0)),"⚠ нет в реестре")))) | I4: Услуга подставлена в корзину визита | J4: Связано | K4: Ссылка на карточке ведёт на BOOK-01, но услуга в корзину НЕ подставляется
A5: L-004 | B5: PUB | C5: PUB-01 | D5: =IFERROR(INDEX(Реестр!$C:$C,MATCH(C5,Реестр!$A:$A,0)),"⚠ нет в реестре") | E5: Карточка мастера в секции «Мастера» | F5: Переход | G5: PUB-05 | H5: =IF(G5="ANCHOR","Прокрутка к секции",IF(G5="EXT","Внешняя ссылка",IF(G5="PARENT","Вернуться туда, откуда открыто",IFERROR(INDEX(Реестр!$C:$C,MATCH(G5,Реестр!$A:$A,0)),"⚠ нет в реестре")))) | J5: Связано | K5: Фото и имя мастера
A6: L-005 | B6: PUB | C6: PUB-01 | D6: =IFERROR(INDEX(Реестр!$C:$C,MATCH(C6,Реестр!$A:$A,0)),"⚠ нет в реестре") | E6: Работа в секции «Работы» | F6: Переход | G6: PUB-05 | H6: =IF(G6="ANCHOR","Прокрутка к секции",IF(G6="EXT","Внешняя ссылка",IF(G6="PARENT","Вернуться туда, откуда открыто",IFERROR(INDEX(Реестр!$C:$C,MATCH(G6,Реестр!$A:$A,0)),"⚠ нет в реестре")))) | I6: Если работа подписана мастером · 25.09.2026: данные для перехода есть: фото → мастер (work_photos.master_id или через booking_item_id → bookings.master_id). Нужно сделать работы кликабельными в прототипе | J6: Связано | K6: Работа в галерее «Наши работы» открывает профиль мастера (#/masters/:id); подпись «Мастер →» на карточке. «Смотреть все работы» заменено на «Работы каждого мастера — в его профиле» (→ #masters). Сделано 25.09.2026
A7: L-006 | B7: PUB | C7: PUB-01 | D7: =IFERROR(INDEX(Реестр!$C:$C,MATCH(C7,Реестр!$A:$A,0)),"⚠ нет в реестре") | E7: Контакты: телефон, карта, соцсети | F7: Внешняя ссылка | G7: EXT | H7: =IF(G7="ANCHOR","Прокрутка к секции",IF(G7="EXT","Внешняя ссылка",IF(G7="PARENT","Вернуться туда, откуда открыто",IFERROR(INDEX(Реестр!$C:$C,MATCH(G7,Реестр!$A:$A,0)),"⚠ нет в реестре")))) | J7: Связано | K7: Только «Позвонить» (tel:). Карта и VK/Telegram — текст
A8: L-007 | B8: PUB | C8: PUB-05 | D8: =IFERROR(INDEX(Реестр!$C:$C,MATCH(C8,Реестр!$A:$A,0)),"⚠ нет в реестре") | E8: Кнопка «Записаться к мастеру» | F8: Переход | G8: BOOK-01 | H8: =IF(G8="ANCHOR","Прокрутка к секции",IF(G8="EXT","Внешняя ссылка",IF(G8="PARENT","Вернуться туда, откуда открыто",IFERROR(INDEX(Реестр!$C:$C,MATCH(G8,Реестр!$A:$A,0)),"⚠ нет в реестре")))) | I8: Мастер уже выбран на шаге услуг | J8: Связано | K8: «Записаться»: без выбранных услуг → BOOK-01 с закреплённым мастером; если услуги уже выбраны → BOOK-03
A9: L-008 | B9: PUB | C9: PUB-05 | D9: =IFERROR(INDEX(Реестр!$C:$C,MATCH(C9,Реестр!$A:$A,0)),"⚠ нет в реестре") | E9: «Все мастера» / назад на лендинг | F9: Назад | G9: PUB-01 | H9: =IF(G9="ANCHOR","Прокрутка к секции",IF(G9="EXT","Внешняя ссылка",IF(G9="PARENT","Вернуться туда, откуда открыто",IFERROR(INDEX(Реестр!$C:$C,MATCH(G9,Реестр!$A:$A,0)),"⚠ нет в реестре")))) | I9: К секции «Мастера» | J9: Связано | K9: «← Назад»: на лендинг, а если пришли с шага «Мастер» — обратно на BOOK-02
A10: L-009 | B10: AUTH | C10: AUTH-01 | D10: =IFERROR(INDEX(Реестр!$C:$C,MATCH(C10,Реестр!$A:$A,0)),"⚠ нет в реестре") | E10: Ссылка «Войти по коду из SMS» | F10: Переход | G10: AUTH-02 | H10: =IF(G10="ANCHOR","Прокрутка к секции",IF(G10="EXT","Внешняя ссылка",IF(G10="PARENT","Вернуться туда, откуда открыто",IFERROR(INDEX(Реестр!$C:$C,MATCH(G10,Реестр!$A:$A,0)),"⚠ нет в реестре")))) | I10: Основной вход — по паролю (L-212) | J10: Связано | K10: Переписано под прототип 25.09.2026
A11: L-010 | B11: AUTH | C11: AUTH-01 | D11: =IFERROR(INDEX(Реестр!$C:$C,MATCH(C11,Реестр!$A:$A,0)),"⚠ нет в реестре") | E11: «Назад» / крестик | F11: Назад | G11: PUB-01 | H11: =IF(G11="ANCHOR","Прокрутка к секции",IF(G11="EXT","Внешняя ссылка",IF(G11="PARENT","Вернуться туда, откуда открыто",IFERROR(INDEX(Реестр!$C:$C,MATCH(G11,Реестр!$A:$A,0)),"⚠ нет в реестре")))) | J11: Нет элемента | K11: На экране входа нет «Назад» и логотипа
A12: L-011 | B12: AUTH | C12: AUTH-02 | D12: =IFERROR(INDEX(Реестр!$C:$C,MATCH(C12,Реестр!$A:$A,0)),"⚠ нет в реестре") | E12: Кнопка «Подтвердить» — клиент пришёл из записи | F12: Переход | G12: BOOK-04 | H12: =IF(G12="ANCHOR","Прокрутка к секции",IF(G12="EXT","Внешняя ссылка",IF(G12="PARENT","Вернуться туда, откуда открыто",IFERROR(INDEX(Реестр!$C:$C,MATCH(G12,Реестр!$A:$A,0)),"⚠ нет в реестре")))) | I12: Условный переход: выбрать демо-ветку | J12: Связано | K12: Кнопки нет — проверка после ввода 4 цифр. Если есть черновик записи → BOOK-04
A13: L-012 | B13: AUTH | C13: AUTH-02 | D13: =IFERROR(INDEX(Реестр!$C:$C,MATCH(C13,Реестр!$A:$A,0)),"⚠ нет в реестре") | E13: Верный код после регистрации | F13: Переход | G13: CAB-01 | H13: =IF(G13="ANCHOR","Прокрутка к секции",IF(G13="EXT","Внешняя ссылка",IF(G13="PARENT","Вернуться туда, откуда открыто",IFERROR(INDEX(Реестр!$C:$C,MATCH(G13,Реестр!$A:$A,0)),"⚠ нет в реестре")))) | I13: Если есть черновик записи — BOOK-04 (L-011) | J13: Связано | K13: Переписано под прототип 25.09.2026
A14: L-013 | B14: AUTH | C14: AUTH-02 | D14: =IFERROR(INDEX(Реестр!$C:$C,MATCH(C14,Реестр!$A:$A,0)),"⚠ нет в реестре") | E14: Ссылка «Изменить номер» | F14: Назад | G14: AUTH-01 | H14: =IF(G14="ANCHOR","Прокрутка к секции",IF(G14="EXT","Внешняя ссылка",IF(G14="PARENT","Вернуться туда, откуда открыто",IFERROR(INDEX(Реестр!$C:$C,MATCH(G14,Реестр!$A:$A,0)),"⚠ нет в реестре")))) | J14: Связано | K14: Возвращает на экран, с которого пришли (вход, регистрация, вход сотрудника, восстановление)
A15: L-014 | B15: AUTH | C15: AUTH-03 | D15: =IFERROR(INDEX(Реестр!$C:$C,MATCH(C15,Реестр!$A:$A,0)),"⚠ нет в реестре") | E15: Кнопка «Зарегистрироваться» | F15: Переход | G15: AUTH-02 | H15: =IF(G15="ANCHOR","Прокрутка к секции",IF(G15="EXT","Внешняя ссылка",IF(G15="PARENT","Вернуться туда, откуда открыто",IFERROR(INDEX(Реестр!$C:$C,MATCH(G15,Реестр!$A:$A,0)),"⚠ нет в реестре")))) | I15: Регистрация до кода: имя, телефон, e-mail, пароль, согласие на обработку ПДн | J15: Связано | K15: Переписано под прототип 25.09.2026 (заменяет L-214)
A16: L-017 | B16: AUTH | C16: AUTH-04 | D16: =IFERROR(INDEX(Реестр!$C:$C,MATCH(C16,Реестр!$A:$A,0)),"⚠ нет в реестре") | E16: Кнопка «Войти» — только администратор | F16: Переход | G16: A-01 | H16: =IF(G16="ANCHOR","Прокрутка к секции",IF(G16="EXT","Внешняя ссылка",IF(G16="PARENT","Вернуться туда, откуда открыто",IFERROR(INDEX(Реестр!$C:$C,MATCH(G16,Реестр!$A:$A,0)),"⚠ нет в реестре")))) | I16: Условный переход | J16: Связано | K16: Тест: +7 (999) 000-11-22 / Admin1234
A17: L-018 | B17: AUTH | C17: AUTH-04 | D17: =IFERROR(INDEX(Реестр!$C:$C,MATCH(C17,Реестр!$A:$A,0)),"⚠ нет в реестре") | E17: Ссылка «Забыли пароль» | F17: Переход | G17: AUTH-06 | H17: =IF(G17="ANCHOR","Прокрутка к секции",IF(G17="EXT","Внешняя ссылка",IF(G17="PARENT","Вернуться туда, откуда открыто",IFERROR(INDEX(Реестр!$C:$C,MATCH(G17,Реестр!$A:$A,0)),"⚠ нет в реестре")))) | J17: Связано
A18: L-022 | B18: AUTH | C18: AUTH-06 | D18: =IFERROR(INDEX(Реестр!$C:$C,MATCH(C18,Реестр!$A:$A,0)),"⚠ нет в реестре") | E18: Кнопка «Отправить» → «Ввести код» | F18: Переход | G18: AUTH-02 | H18: =IF(G18="ANCHOR","Прокрутка к секции",IF(G18="EXT","Внешняя ссылка",IF(G18="PARENT","Вернуться туда, откуда открыто",IFERROR(INDEX(Реестр!$C:$C,MATCH(G18,Реестр!$A:$A,0)),"⚠ нет в реестре")))) | I18: После «Отправить» на том же экране — «Проверьте телефон или почту»; дальше AUTH-02 → AUTH-08 (L-217) | J18: Связано | K18: Переписано под прототип 25.09.2026 (заменяет L-218)
A19: L-023 | B19: AUTH | C19: AUTH-06 | D19: =IFERROR(INDEX(Реестр!$C:$C,MATCH(C19,Реестр!$A:$A,0)),"⚠ нет в реестре") | E19: «Назад ко входу» | F19: Назад | G19: AUTH-04 | H19: =IF(G19="ANCHOR","Прокрутка к секции",IF(G19="EXT","Внешняя ссылка",IF(G19="PARENT","Вернуться туда, откуда открыто",IFERROR(INDEX(Реестр!$C:$C,MATCH(G19,Реестр!$A:$A,0)),"⚠ нет в реестре")))) | J19: Связано | K19: «Вернуться ко входу» → AUTH-01 или AUTH-04, откуда пришли
A20: L-026 | B20: BOOK | C20: BOOK-01 | D20: =IFERROR(INDEX(Реестр!$C:$C,MATCH(C20,Реестр!$A:$A,0)),"⚠ нет в реестре") | E20: Карточка услуги (добавить в корзину визита) | F20: Переход | G20: BOOK-01 | H20: =IF(G20="ANCHOR","Прокрутка к секции",IF(G20="EXT","Внешняя ссылка",IF(G20="PARENT","Вернуться туда, откуда открыто",IFERROR(INDEX(Реестр!$C:$C,MATCH(G20,Реестр!$A:$A,0)),"⚠ нет в реестре")))) | I20: Выбор без ухода со страницы, мультивыбор | J20: Связано | K20: Кнопка «Добавить» на карточке; клик по карточке открывает детали BOOK-M4
A21: L-027 | B21: BOOK | C21: BOOK-01 | D21: =IFERROR(INDEX(Реестр!$C:$C,MATCH(C21,Реестр!$A:$A,0)),"⚠ нет в реестре") | E21: Кнопка «Далее» | F21: Переход | G21: BOOK-02 | H21: =IF(G21="ANCHOR","Прокрутка к секции",IF(G21="EXT","Внешняя ссылка",IF(G21="PARENT","Вернуться туда, откуда открыто",IFERROR(INDEX(Реестр!$C:$C,MATCH(G21,Реестр!$A:$A,0)),"⚠ нет в реестре")))) | J21: Связано | K21: Кнопка в плашке корзины
A22: L-028 | B22: BOOK | C22: BOOK-01 | D22: =IFERROR(INDEX(Реестр!$C:$C,MATCH(C22,Реестр!$A:$A,0)),"⚠ нет в реестре") | E22: Кнопка «Далее» при входе из профиля мастера | F22: Переход | G22: BOOK-03 | H22: =IF(G22="ANCHOR","Прокрутка к секции",IF(G22="EXT","Внешняя ссылка",IF(G22="PARENT","Вернуться туда, откуда открыто",IFERROR(INDEX(Реестр!$C:$C,MATCH(G22,Реестр!$A:$A,0)),"⚠ нет в реестре")))) | I22: Мастер уже выбран, шаг 2 пропускается. Условный переход | J22: Связано | K22: Реализовано: при закреплённом мастере кнопка ведёт сразу на BOOK-03
A23: L-029 | B23: BOOK | C23: BOOK-02 | D23: =IFERROR(INDEX(Реестр!$C:$C,MATCH(C23,Реестр!$A:$A,0)),"⚠ нет в реестре") | E23: Карточка мастера | F23: Переход | G23: BOOK-03 | H23: =IF(G23="ANCHOR","Прокрутка к секции",IF(G23="EXT","Внешняя ссылка",IF(G23="PARENT","Вернуться туда, откуда открыто",IFERROR(INDEX(Реестр!$C:$C,MATCH(G23,Реестр!$A:$A,0)),"⚠ нет в реестре")))) | J23: Связано
A24: L-030 | B24: BOOK | C24: BOOK-02 | D24: =IFERROR(INDEX(Реестр!$C:$C,MATCH(C24,Реестр!$A:$A,0)),"⚠ нет в реестре") | E24: Вариант «Любой мастер» | F24: Переход | G24: BOOK-03 | H24: =IF(G24="ANCHOR","Прокрутка к секции",IF(G24="EXT","Внешняя ссылка",IF(G24="PARENT","Вернуться туда, откуда открыто",IFERROR(INDEX(Реестр!$C:$C,MATCH(G24,Реестр!$A:$A,0)),"⚠ нет в реестре")))) | J24: Связано | K24: «Любой свободный мастер»
A25: L-031 | B25: BOOK | C25: BOOK-02 | D25: =IFERROR(INDEX(Реестр!$C:$C,MATCH(C25,Реестр!$A:$A,0)),"⚠ нет в реестре") | E25: «Назад» | F25: Назад | G25: BOOK-01 | H25: =IF(G25="ANCHOR","Прокрутка к секции",IF(G25="EXT","Внешняя ссылка",IF(G25="PARENT","Вернуться туда, откуда открыто",IFERROR(INDEX(Реестр!$C:$C,MATCH(G25,Реестр!$A:$A,0)),"⚠ нет в реестре")))) | J25: Связано | K25: «← Назад» в шапке записи
A26: L-032 | B26: BOOK | C26: BOOK-03 | D26: =IFERROR(INDEX(Реестр!$C:$C,MATCH(C26,Реестр!$A:$A,0)),"⚠ нет в реестре") | E26: Свободный слот времени | F26: Переход | G26: BOOK-04 | H26: =IF(G26="ANCHOR","Прокрутка к секции",IF(G26="EXT","Внешняя ссылка",IF(G26="PARENT","Вернуться туда, откуда открыто",IFERROR(INDEX(Реестр!$C:$C,MATCH(G26,Реестр!$A:$A,0)),"⚠ нет в реестре")))) | J26: Связано | K26: Слот выбирается, переход — кнопкой «Продолжить». Без авторизации → AUTH-01
A27: L-034 | B27: BOOK | C27: BOOK-04 | D27: =IFERROR(INDEX(Реестр!$C:$C,MATCH(C27,Реестр!$A:$A,0)),"⚠ нет в реестре") | E27: Кнопка «Записаться», если время уже заняли | F27: Модалка | G27: BOOK-M1 | H27: =IF(G27="ANCHOR","Прокрутка к секции",IF(G27="EXT","Внешняя ссылка",IF(G27="PARENT","Вернуться туда, откуда открыто",IFERROR(INDEX(Реестр!$C:$C,MATCH(G27,Реестр!$A:$A,0)),"⚠ нет в реестре")))) | I27: Сценарий «Слот заняли» в панели разработчика. На BOOK-03 показываются только свободные слоты | J27: Связано | K27: Переписано под прототип 25.09.2026
A28: L-035 | B28: BOOK | C28: BOOK-03 | D28: =IFERROR(INDEX(Реестр!$C:$C,MATCH(C28,Реестр!$A:$A,0)),"⚠ нет в реестре") | E28: «Назад» | F28: Назад | G28: BOOK-02 | H28: =IF(G28="ANCHOR","Прокрутка к секции",IF(G28="EXT","Внешняя ссылка",IF(G28="PARENT","Вернуться туда, откуда открыто",IFERROR(INDEX(Реестр!$C:$C,MATCH(G28,Реестр!$A:$A,0)),"⚠ нет в реестре")))) | J28: Связано | K28: «← Назад» в шапке записи
A29: L-038 | B29: BOOK | C29: BOOK-M1 | D29: =IFERROR(INDEX(Реестр!$C:$C,MATCH(C29,Реестр!$A:$A,0)),"⚠ нет в реестре") | E29: Кнопка «Выбрать другое время» | F29: Закрыть оверлей | G29: BOOK-03 | H29: =IF(G29="ANCHOR","Прокрутка к секции",IF(G29="EXT","Внешняя ссылка",IF(G29="PARENT","Вернуться туда, откуда открыто",IFERROR(INDEX(Реестр!$C:$C,MATCH(G29,Реестр!$A:$A,0)),"⚠ нет в реестре")))) | J29: Связано | K29: Плюс чипсы альтернативного времени
A30: L-040 | B30: BOOK | C30: BOOK-03 | D30: =IFERROR(INDEX(Реестр!$C:$C,MATCH(C30,Реестр!$A:$A,0)),"⚠ нет в реестре") | E30: Кнопка «Продолжить» без авторизации | F30: Переход | G30: AUTH-01 | H30: =IF(G30="ANCHOR","Прокрутка к секции",IF(G30="EXT","Внешняя ссылка",IF(G30="PARENT","Вернуться туда, откуда открыто",IFERROR(INDEX(Реестр!$C:$C,MATCH(G30,Реестр!$A:$A,0)),"⚠ нет в реестре")))) | I30: После входа — сразу BOOK-04 | J30: Связано | K30: Переписано под прототип 25.09.2026 (заменяет L-230)
A31: L-041 | B31: BOOK | C31: BOOK-04 | D31: =IFERROR(INDEX(Реестр!$C:$C,MATCH(C31,Реестр!$A:$A,0)),"⚠ нет в реестре") | E31: Кнопка «Записаться» | F31: Переход | G31: BOOK-05 | H31: =IF(G31="ANCHOR","Прокрутка к секции",IF(G31="EXT","Внешняя ссылка",IF(G31="PARENT","Вернуться туда, откуда открыто",IFERROR(INDEX(Реестр!$C:$C,MATCH(G31,Реестр!$A:$A,0)),"⚠ нет в реестре")))) | J31: Связано
A32: L-042 | B32: BOOK | C32: BOOK-04 | D32: =IFERROR(INDEX(Реестр!$C:$C,MATCH(C32,Реестр!$A:$A,0)),"⚠ нет в реестре") | E32: Ошибка при отправке (демо) | F32: Переход | G32: BOOK-06 | H32: =IF(G32="ANCHOR","Прокрутка к секции",IF(G32="EXT","Внешняя ссылка",IF(G32="PARENT","Вернуться туда, откуда открыто",IFERROR(INDEX(Реестр!$C:$C,MATCH(G32,Реестр!$A:$A,0)),"⚠ нет в реестре")))) | I32: Условный переход | J32: Связано | K32: Сценарий «Ошибка сервера» в панели разработчика
A33: L-043 | B33: BOOK | C33: BOOK-04 | D33: =IFERROR(INDEX(Реестр!$C:$C,MATCH(C33,Реестр!$A:$A,0)),"⚠ нет в реестре") | E33: «Изменить» у услуг | F33: Переход | G33: BOOK-01 | H33: =IF(G33="ANCHOR","Прокрутка к секции",IF(G33="EXT","Внешняя ссылка",IF(G33="PARENT","Вернуться туда, откуда открыто",IFERROR(INDEX(Реестр!$C:$C,MATCH(G33,Реестр!$A:$A,0)),"⚠ нет в реестре")))) | J33: Связано
A34: L-044 | B34: BOOK | C34: BOOK-04 | D34: =IFERROR(INDEX(Реестр!$C:$C,MATCH(C34,Реестр!$A:$A,0)),"⚠ нет в реестре") | E34: «Изменить» у мастера | F34: Переход | G34: BOOK-02 | H34: =IF(G34="ANCHOR","Прокрутка к секции",IF(G34="EXT","Внешняя ссылка",IF(G34="PARENT","Вернуться туда, откуда открыто",IFERROR(INDEX(Реестр!$C:$C,MATCH(G34,Реестр!$A:$A,0)),"⚠ нет в реестре")))) | J34: Связано
A35: L-045 | B35: BOOK | C35: BOOK-04 | D35: =IFERROR(INDEX(Реестр!$C:$C,MATCH(C35,Реестр!$A:$A,0)),"⚠ нет в реестре") | E35: «Изменить» у времени | F35: Переход | G35: BOOK-03 | H35: =IF(G35="ANCHOR","Прокрутка к секции",IF(G35="EXT","Внешняя ссылка",IF(G35="PARENT","Вернуться туда, откуда открыто",IFERROR(INDEX(Реестр!$C:$C,MATCH(G35,Реестр!$A:$A,0)),"⚠ нет в реестре")))) | J35: Связано
